<?xml version="1.0" encoding="UTF-8"?>
<!-- Generated by org.testng.reporters.JUnitXMLReporter -->
<testsuite hostname="LAPTOP-FQNG9GGL" ignored="0" name="这是我自己的测试方法" tests="4" failures="3" timestamp="13 三月 2020 10:58:10 GMT" time="0.081" errors="0">
  <testcase name="logDemo" time="0.018" classname="com.course.extentreport.TestMethodDemo">
    <failure type="java.lang.RuntimeException" message="这是我自己运行时的异常">
      <![CDATA[java.lang.RuntimeException: 这是我自己运行时的异常
	at com.course.extentreport.TestMethodDemo.logDemo(TestMethodDemo.java:23)
	at com.intellij.rt.testng.IDEARemoteTestNG.run(IDEARemoteTestNG.java:66)
	at com.intellij.rt.testng.RemoteTestNGStarter.main(RemoteTestNGStarter.java:110)
... Removed 22 stack frames]]>
    </failure>
  </testcase> <!-- logDemo -->
  <testcase name="test1" time="0.0" classname="com.course.extentreport.TestMethodDemo"/>
  <testcase name="test2" time="0.0" classname="com.course.extentreport.TestMethodDemo">
    <failure type="java.lang.AssertionError" message="expected [2] but found [1]">
      <![CDATA[java.lang.AssertionError: expected [2] but found [1]
	at com.course.extentreport.TestMethodDemo.test2(TestMethodDemo.java:14)
	at com.intellij.rt.testng.IDEARemoteTestNG.run(IDEARemoteTestNG.java:66)
	at com.intellij.rt.testng.RemoteTestNGStarter.main(RemoteTestNGStarter.java:110)
... Removed 28 stack frames]]>
    </failure>
  </testcase> <!-- test2 -->
  <testcase name="test3" time="0.0" classname="com.course.extentreport.TestMethodDemo">
    <failure type="java.lang.AssertionError" message="expected [bbb] but found [aaa]">
      <![CDATA[java.lang.AssertionError: expected [bbb] but found [aaa]
	at com.course.extentreport.TestMethodDemo.test3(TestMethodDemo.java:18)
	at com.intellij.rt.testng.IDEARemoteTestNG.run(IDEARemoteTestNG.java:66)
	at com.intellij.rt.testng.RemoteTestNGStarter.main(RemoteTestNGStarter.java:110)
... Removed 28 stack frames]]>
    </failure>
  </testcase> <!-- test3 -->
</testsuite> <!-- 这是我自己的测试方法 -->
